Workbook

Sheet Assumptions
A1: Assumption | B1: Value | C1: Unit | D1: Source / Citation
A2: PRICING
A3: Pro Tier — Monthly | B3: 4.99 | C3: USD/mo
A4: Commissioner Tier — Monthly | B4: 9.99 | C4: USD/mo
A5: Annual Billing Discount | B5: 0.2 | C5: % | D5: Industry standard
A6: Annual Billing % | B6: 0.3 | C6: % | D6: Industry benchmarks
A7: Monthly Billing % | B7: 0.7 | C7: %
A9: CONVERSION RATES
A10: Premium Features Launch Threshold | B10: 10000 | C10: users | D10: No paid tiers until user base hits this
A11: Free → Pro Y1 | B11: 0.025 | C11: % | D11: RevenueCat median 2.18%; niche premium
A12: Free → Pro Y2 | B12: 0.055 | C12: % | D12: Product maturation + mobile
A13: Free → Commissioner Y1 | B13: 0.008 | C13: % | D13: Power-user tier
A14: Free → Commissioner Y2 | B14: 0.015 | C14: %
A15: In-Season Multiplier | B15: 1.8 | C15: x | D15: NHL engagement seasonality
A16: Off-Season Multiplier | B16: 0.4 | C16: x
A18: CHURN RATES (Monthly)
A19: Pro In-Season | B19: 0.04 | C19: % | D19: Below mobile avg 9%
A20: Pro Off-Season | B20: 0.12 | C20: % | D20: Seasonal disengagement
A21: Commissioner In-Season | B21: 0.025 | C21: % | D21: Stickier — league mgmt
A22: Commissioner Off-Season | B22: 0.08 | C22: %
A23: Free In-Season | B23: 0.06 | C23: %
A24: Free Off-Season | B24: 0.15 | C24: %
A26: STORMY AI — TOKEN BUDGETS (per tier)
A27: Free Tier Tokens/mo | B27: 5000 | C27: tokens | D27: ~2-3 short questions
A28: Pro Tier Tokens/mo | B28: 50000 | C28: tokens | D28: ~25 questions/mo
A29: Commissioner Tier Tokens/mo | B29: 150000 | C29: tokens | D29: ~75 questions/mo
A31: PAY-PER-USE (Token Top-Up Packs)
A32: Free User Token Pack | B32: 2.99 | C32: USD | D32: 25K tokens — $0.12/1K (premium)
A33: Paid User Token Pack | B33: 1.99 | C33: USD | D33: 100K tokens — $0.02/1K (subscriber perk)
A34: Top-Up Attach — Free Users | B34: 0.03 | C34: %/mo | D34: Hit limit, want more
A35: Top-Up Attach — Pro/Comm | B35: 0.08 | C35: %/mo | D35: Power users exceeding budget
A36: Draft Kit Price | B36: 4.99 | C36: USD | D36: One-time per season
A37: Draft Kit Attach Rate | B37: 0.08 | C37: % | D37: All users in draft months
A39: DFS
A40: DFS Rake | B40: 0.12 | C40: % | D40: DK/FD range 10-16%
A41: Average Entry Fee | B41: 5 | C41: USD
A42: Participation Rate | B42: 0.05 | C42: % | D42: Hockey-only; DK ~10% all sports
A43: Entries per User per Month | B43: 5 | C43: #
A44: DFS Launch Month Index | B44: 18 | C44: 0-based | D44: Oct 2027
A46: ADVERTISING (web only — no mobile app ads)
...

Sheet User Growth
A1: Metric | B1: Apr-26 | C1: May-26 | D1: Jun-26 | E1: Jul-26 | F1: Aug-26 | G1: Sep-26 | H1: Oct-26 | I1: Nov-26 | J1: Dec-26 | K1: Jan-27 | L1: Feb-27 | M1: Mar-27 | N1: Apr-27 | O1: May-27 | P1: Jun-27 | Q1: Jul-27 | R1: Aug-27 | S1: Sep-27 | T1: Oct-27 | U1: Nov-27 | V1: Dec-27 | W1: Jan-28 | X1: Feb-28 | Y1: Mar-28
A2: NHL Season Status | B2: OFF-SEASON | C2: OFF-SEASON | D2: OFF-SEASON | E2: OFF-SEASON | F2: OFF-SEASON | G2: OFF-SEASON | H2: IN-SEASON | I2: IN-SEASON | J2: IN-SEASON | K2: IN-SEASON | L2: IN-SEASON | M2: IN-SEASON | N2: OFF-SEASON | O2: OFF-SEASON | P2: OFF-SEASON | Q2: OFF-SEASON | R2: OFF-SEASON | S2: OFF-SEASON | T2: IN-SEASON | U2: IN-SEASON | V2: IN-SEASON | W2: IN-SEASON | X2: IN-SEASON | Y2: IN-SEASON
A3: New Users Acquired | B3: =Assumptions!$B$174 | C3: =Assumptions!$B$175 | D3: =Assumptions!$B$176 | E3: =Assumptions!$B$177 | F3: =Assumptions!$B$178 | G3: =Assumptions!$B$179 | H3: =Assumptions!$B$180 | I3: =Assumptions!$B$181 | J3: =Assumptions!$B$182 | K3: =Assumptions!$B$183 | L3: =Assumptions!$B$184 | M3: =Assumptions!$B$185 | N3: =Assumptions!$B$186 | O3: =Assumptions!$B$187 | P3: =Assumptions!$B$188 | Q3: =Assumptions!$B$189 | R3: =Assumptions!$B$190 | S3: =Assumptions!$B$191 | T3: =Assumptions!$B$192 | U3: =Assumptions!$B$193 | V3: =Assumptions!$B$194 | W3: =Assumptions!$B$195 | X3: =Assumptions!$B$196 | Y3: =Assumptions!$B$197
A5: Eff. Conv Rate → Pro | B5: =IF(0>=Assumptions!$B$10,IF(COLUMN()<14,Assumptions!$B$11,Assumptions!$B$12)*IF(B2="IN-SEASON",Assumptions!$B$15,Assumptions!$B$16),0) | C5: =IF(B20>=Assumptions!$B$10,IF(COLUMN()<14,Assumptions!$B$11,Assumptions!$B$12)*IF(C2="IN-SEASON",Assumptions!$B$15,Assumptions!$B$16),0) | D5: =IF(C20>=Assumptions!$B$10,IF(COLUMN()<14,Assumptions!$B$11,Assumptions!$B$12)*IF(D2="IN-SEASON",Assumptions!$B$15,Assumptions!$B$16),0) | E5: =IF(D20>=Assumptions!$B$10,IF(COLUMN()<14,Assumptions!$B$11,Assumptions!$B$12)*IF(E2="IN-SEASON",Assumptions!$B$15,Assumptions!$B$16),0) | F5: =IF(E20>=Assumptions!$B$10,IF(COLUMN()<14,Assumptions!$B$11,Assumptions!$B$12)*IF(F2="IN-SEASON",Assumptions!$B$15,Assumptions!$B$16),0) | G5: =IF(F20>=Assumptions!$B$10,IF(COLUMN()<14,Assumptions!$B$11,Assumptions!$B$12)*IF(G2="IN-SEASON",Assumptions!$B$15,Assumptions!$B$16),0) | H5: =IF(G20>=Assumptions!$B$10,IF(COLUMN()<14,Assumptions!$B$11,Assumptions!$B$12)*IF(H2="IN-SEASON",Assumptions!$B$15,Assumptions!$B$16),0) | I5: =IF(H20>=Assumptions!$B$10,IF(COLUMN()<14,Assumptions!$B$11,Assumptions!$B$12)*IF(I2="IN-SEASON",Assumptions!$B$15,Assumptions!$B$16),0) | J5: =IF(I20>=Assumptions!$B$10,IF(COLUMN()<14,Assumptions!$B$11,Assumptions!$B$12)*IF(J2="IN-SEASON",Assumptions!$B$15,Assumptions!$B$16),0) | ... Y5: =IF(X20>=Assumptions!$B$10,IF(COLUMN()<14,Assumptions!$B$11,Assumptions!$B$12)*IF(Y2="IN-SEASON",Assumptions!$B$15,Assumptions!$B$16),0)
A6: Eff. Conv Rate → Comm | B6: =IF(0>=Assumptions!$B$10,IF(COLUMN()<14,Assumptions!$B$13,Assumptions!$B$14)*IF(B2="IN-SEASON",Assumptions!$B$15,Assumptions!$B$16),0) | C6: =IF(B20>=Assumptions!$B$10,IF(COLUMN()<14,Assumptions!$B$13,Assumptions!$B$14)*IF(C2="IN-SEASON",Assumptions!$B$15,Assumptions!$B$16),0) | D6: =IF(C20>=Assumptions!$B$10,IF(COLUMN()<14,Assumptions!$B$13,Assumptions!$B$14)*IF(D2="IN-SEASON",Assumptions!$B$15,Assumptions!$B$16),0) | E6: =IF(D20>=Assumptions!$B$10,IF(COLUMN()<14,Assumptions!$B$13,Assumptions!$B$14)*IF(E2="IN-SEASON",Assumptions!$B$15,Assumptions!$B$16),0) | F6: =IF(E20>=Assumptions!$B$10,IF(COLUMN()<14,Assumptions!$B$13,Assumptions!$B$14)*IF(F2="IN-SEASON",Assumptions!$B$15,Assumptions!$B$16),0) | G6: =IF(F20>=Assumptions!$B$10,IF(COLUMN()<14,Assumptions!$B$13,Assumptions!$B$14)*IF(G2="IN-SEASON",Assumptions!$B$15,Assumptions!$B$16),0) | H6: =IF(G20>=Assumptions!$B$10,IF(COLUMN()<14,Assumptions!$B$13,Assumptions!$B$14)*IF(H2="IN-SEASON",Assumptions!$B$15,Assumptions!$B$16),0) | I6: =IF(H20>=Assumptions!$B$10,IF(COLUMN()<14,Assumptions!$B$13,Assumptions!$B$14)*IF(I2="IN-SEASON",Assumptions!$B$15,Assumptions!$B$16),0) | J6: =IF(I20>=Assumptions!$B$10,IF(COLUMN()<14,Assumptions!$B$13,Assumptions!$B$14)*IF(J2="IN-SEASON",Assumptions!$B$15,Assumptions!$B$16),0) | ... Y6: =IF(X20>=Assumptions!$B$10,IF(COLUMN()<14,Assumptions!$B$13,Assumptions!$B$14)*IF(Y2="IN-SEASON",Assumptions!$B$15,Assumptions!$B$16),0)
A7: Churn Rate (Free) | B7: =IF(B2="IN-SEASON",Assumptions!$B$23,Assumptions!$B$24) | C7: =IF(C2="IN-SEASON",Assumptions!$B$23,Assumptions!$B$24) | D7: =IF(D2="IN-SEASON",Assumptions!$B$23,Assumptions!$B$24) | E7: =IF(E2="IN-SEASON",Assumptions!$B$23,Assumptions!$B$24) | F7: =IF(F2="IN-SEASON",Assumptions!$B$23,Assumptions!$B$24) | G7: =IF(G2="IN-SEASON",Assumptions!$B$23,Assumptions!$B$24) | H7: =IF(H2="IN-SEASON",Assumptions!$B$23,Assumptions!$B$24) | I7: =IF(I2="IN-SEASON",Assumptions!$B$23,Assumptions!$B$24) | ... Y7: =IF(Y2="IN-SEASON",Assumptions!$B$23,Assumptions!$B$24)
A8: Churn Rate (Pro) | B8: =IF(B2="IN-SEASON",Assumptions!$B$19,Assumptions!$B$20) | C8: =IF(C2="IN-SEASON",Assumptions!$B$19,Assumptions!$B$20) | D8: =IF(D2="IN-SEASON",Assumptions!$B$19,Assumptions!$B$20) | E8: =IF(E2="IN-SEASON",Assumptions!$B$19,Assumptions!$B$20) | F8: =IF(F2="IN-SEASON",Assumptions!$B$19,Assumptions!$B$20) | G8: =IF(G2="IN-SEASON",Assumptions!$B$19,Assumptions!$B$20) | H8: =IF(H2="IN-SEASON",Assumptions!$B$19,Assumptions!$B$20) | I8: =IF(I2="IN-SEASON",Assumptions!$B$19,Assumptions!$B$20) | ... Y8: =IF(Y2="IN-SEASON",Assumptions!$B$19,Assumptions!$B$20)
A9: Churn Rate (Comm) | B9: =IF(B2="IN-SEASON",Assumptions!$B$21,Assumptions!$B$22) | C9: =IF(C2="IN-SEASON",Assumptions!$B$21,Assumptions!$B$22) | D9: =IF(D2="IN-SEASON",Assumptions!$B$21,Assumptions!$B$22) | E9: =IF(E2="IN-SEASON",Assumptions!$B$21,Assumptions!$B$22) | F9: =IF(F2="IN-SEASON",Assumptions!$B$21,Assumptions!$B$22) | G9: =IF(G2="IN-SEASON",Assumptions!$B$21,Assumptions!$B$22) | H9: =IF(H2="IN-SEASON",Assumptions!$B$21,Assumptions!$B$22) | I9: =IF(I2="IN-SEASON",Assumptions!$B$21,Assumptions!$B$22) | ... Y9: =IF(Y2="IN-SEASON",Assumptions!$B$21,Assumptions!$B$22)
A11: Churned Free Users | B11: =INT(0*B7) | C11: =INT(B17*C7) | D11: =INT(C17*D7) | E11: =INT(D17*E7) | F11: =INT(E17*F7) | G11: =INT(F17*G7) | H11: =INT(G17*H7) | I11: =INT(H17*I7) | J11: =INT(I17*J7) | ... Y11: =INT(X17*Y7)
A12: Churned Pro Users | B12: =INT(0*B8) | C12: =INT(B18*C8) | D12: =INT(C18*D8) | E12: =INT(D18*E8) | F12: =INT(E18*F8) | G12: =INT(F18*G8) | H12: =INT(G18*H8) | I12: =INT(H18*I8) | J12: =INT(I18*J8) | ... Y12: =INT(X18*Y8)
A13: Churned Commissioner Users | B13: =INT(0*B9) | C13: =INT(B19*C9) | D13: =INT(C19*D9) | E13: =INT(D19*E9) | F13: =INT(E19*F9) | G13: =INT(F19*G9) | H13: =INT(G19*H9) | I13: =INT(H19*I9) | J13: =INT(I19*J9) | ... Y13: =INT(X19*Y9)
A14: Conversions to Pro | B14: =INT(0*B5) | C14: =INT(B17*C5) | D14: =INT(C17*D5) | E14: =INT(D17*E5) | F14: =INT(E17*F5) | G14: =INT(F17*G5) | H14: =INT(G17*H5) | I14: =INT(H17*I5) | J14: =INT(I17*J5) | ... Y14: =INT(X17*Y5)
A15: Conversions to Commissioner | B15: =INT(0*B6) | C15: =INT(B17*C6) | D15: =INT(C17*D6) | E15: =INT(D17*E6) | F15: =INT(E17*F6) | G15: =INT(F17*G6) | H15: =INT(G17*H6) | I15: =INT(H17*I6) | J15: =INT(I17*J6) | ... Y15: =INT(X17*Y6)
A17: End-of-Month Free Users | B17: =MAX(0,0+B3-B11-B14-B15) | C17: =MAX(0,B17+C3-C11-C14-C15) | D17: =MAX(0,C17+D3-D11-D14-D15) | E17: =MAX(0,D17+E3-E11-E14-E15) | F17: =MAX(0,E17+F3-F11-F14-F15) | G17: =MAX(0,F17+G3-G11-G14-G15) | H17: =MAX(0,G17+H3-H11-H14-H15) | I17: =MAX(0,H17+I3-I11-I14-I15) | J17: =MAX(0,I17+J3-J11-J14-J15) | ... Y17: =MAX(0,X17+Y3-Y11-Y14-Y15)
A18: End-of-Month Pro Users | B18: =MAX(0,0+B14-B12) | C18: =MAX(0,B18+C14-C12) | D18: =MAX(0,C18+D14-D12) | E18: =MAX(0,D18+E14-E12) | F18: =MAX(0,E18+F14-F12) | G18: =MAX(0,F18+G14-G12) | H18: =MAX(0,G18+H14-H12) | I18: =MAX(0,H18+I14-I12) | J18: =MAX(0,I18+J14-J12) | ... Y18: =MAX(0,X18+Y14-Y12)
A19: End-of-Month Commissioner Users | B19: =MAX(0,0+B15-B13) | C19: =MAX(0,B19+C15-C13) | D19: =MAX(0,C19+D15-D13) | E19: =MAX(0,D19+E15-E13) | F19: =MAX(0,E19+F15-F13) | G19: =MAX(0,F19+G15-G13) | H19: =MAX(0,G19+H15-H13) | I19: =MAX(0,H19+I15-I13) | J19: =MAX(0,I19+J15-J13) | ... Y19: =MAX(0,X19+Y15-Y13)
A20: End-of-Month TOTAL Users | B20: =B17+B18+B19 | C20: =C17+C18+C19 | D20: =D17+D18+D19 | E20: =E17+E18+E19 | F20: =F17+F18+F19 | G20: =G17+G18+G19 | H20: =H17+H18+H19 | I20: =I17+I18+I19 | ... Y20: =Y17+Y18+Y19
A22: Premium % of Total | B22: =IF(B20>0,(B18+B19)/B20,0) | C22: =IF(C20>0,(C18+C19)/C20,0) | D22: =IF(D20>0,(D18+D19)/D20,0) | E22: =IF(E20>0,(E18+E19)/E20,0) | F22: =IF(F20>0,(F18+F19)/F20,0) | G22: =IF(G20>0,(G18+G19)/G20,0) | H22: =IF(H20>0,(H18+H19)/H20,0) | I22: =IF(I20>0,(I18+I19)/I20,0) | ... Y22: =IF(Y20>0,(Y18+Y19)/Y20,0)
A23: Blended Monthly Churn Rate | B23: =IF(B20+B11+B12+B13>0,(B11+B12+B13)/(B20+B11+B12+B13),0) | C23: =IF(C20+C11+C12+C13>0,(C11+C12+C13)/(C20+C11+C12+C13),0) | D23: =IF(D20+D11+D12+D13>0,(D11+D12+D13)/(D20+D11+D12+D13),0) | E23: =IF(E20+E11+E12+E13>0,(E11+E12+E13)/(E20+E11+E12+E13),0) | F23: =IF(F20+F11+F12+F13>0,(F11+F12+F13)/(F20+F11+F12+F13),0) | G23: =IF(G20+G11+G12+G13>0,(G11+G12+G13)/(G20+G11+G12+G13),0) | H23: =IF(H20+H11+H12+H13>0,(H11+H12+H13)/(H20+H11+H12+H13),0) | I23: =IF(I20+I11+I12+I13>0,(I11+I12+I13)/(I20+I11+I12+I13),0) | ... Y23: =IF(Y20+Y11+Y12+Y13>0,(Y11+Y12+Y13)/(Y20+Y11+Y12+Y13),0)
A24: Monthly Retention Rate | B24: =1-B23 | C24: =1-C23 | D24: =1-D23 | E24: =1-E23 | F24: =1-F23 | G24: =1-G23 | H24: =1-H23 | I24: =1-I23 | ... Y24: =1-Y23

Sheet Revenue
A1: Revenue Line | B1: Apr-26 | C1: May-26 | D1: Jun-26 | E1: Jul-26 | F1: Aug-26 | G1: Sep-26 | H1: Oct-26 | I1: Nov-26 | J1: Dec-26 | K1: Jan-27 | L1: Feb-27 | M1: Mar-27 | N1: Apr-27 | O1: May-27 | P1: Jun-27 | Q1: Jul-27 | R1: Aug-27 | S1: Sep-27 | T1: Oct-27 | U1: Nov-27 | V1: Dec-27 | W1: Jan-28 | X1: Feb-28 | Y1: Mar-28
A2: SUBSCRIPTION REVENUE
A3: Pro Monthly Billing | B3: =IF('User Growth'!B2="IN-SEASON",'User Growth'!B18*Assumptions!$B$7*Assumptions!$B$3,0) | C3: =IF('User Growth'!C2="IN-SEASON",'User Growth'!C18*Assumptions!$B$7*Assumptions!$B$3,0) | D3: =IF('User Growth'!D2="IN-SEASON",'User Growth'!D18*Assumptions!$B$7*Assumptions!$B$3,0) | E3: =IF('User Growth'!E2="IN-SEASON",'User Growth'!E18*Assumptions!$B$7*Assumptions!$B$3,0) | F3: =IF('User Growth'!F2="IN-SEASON",'User Growth'!F18*Assumptions!$B$7*Assumptions!$B$3,0) | G3: =IF('User Growth'!G2="IN-SEASON",'User Growth'!G18*Assumptions!$B$7*Assumptions!$B$3,0) | H3: =IF('User Growth'!H2="IN-SEASON",'User Growth'!H18*Assumptions!$B$7*Assumptions!$B$3,0) | I3: =IF('User Growth'!I2="IN-SEASON",'User Growth'!I18*Assumptions!$B$7*Assumptions!$B$3,0) | ... Y3: =IF('User Growth'!Y2="IN-SEASON",'User Growth'!Y18*Assumptions!$B$7*Assumptions!$B$3,0)
A4: Pro Annual Billing | B4: ='User Growth'!B18*Assumptions!$B$6*Assumptions!$B$3 | C4: ='User Growth'!C18*Assumptions!$B$6*Assumptions!$B$3 | D4: ='User Growth'!D18*Assumptions!$B$6*Assumptions!$B$3 | E4: ='User Growth'!E18*Assumptions!$B$6*Assumptions!$B$3 | F4: ='User Growth'!F18*Assumptions!$B$6*Assumptions!$B$3 | G4: ='User Growth'!G18*Assumptions!$B$6*Assumptions!$B$3 | H4: ='User Growth'!H18*Assumptions!$B$6*Assumptions!$B$3 | I4: ='User Growth'!I18*Assumptions!$B$6*Assumptions!$B$3 | ... Y4: ='User Growth'!Y18*Assumptions!$B$6*Assumptions!$B$3
A5: Commissioner Monthly Billing | B5: =IF('User Growth'!B2="IN-SEASON",'User Growth'!B19*Assumptions!$B$7*Assumptions!$B$4,0) | C5: =IF('User Growth'!C2="IN-SEASON",'User Growth'!C19*Assumptions!$B$7*Assumptions!$B$4,0) | D5: =IF('User Growth'!D2="IN-SEASON",'User Growth'!D19*Assumptions!$B$7*Assumptions!$B$4,0) | E5: =IF('User Growth'!E2="IN-SEASON",'User Growth'!E19*Assumptions!$B$7*Assumptions!$B$4,0) | F5: =IF('User Growth'!F2="IN-SEASON",'User Growth'!F19*Assumptions!$B$7*Assumptions!$B$4,0) | G5: =IF('User Growth'!G2="IN-SEASON",'User Growth'!G19*Assumptions!$B$7*Assumptions!$B$4,0) | H5: =IF('User Growth'!H2="IN-SEASON",'User Growth'!H19*Assumptions!$B$7*Assumptions!$B$4,0) | I5: =IF('User Growth'!I2="IN-SEASON",'User Growth'!I19*Assumptions!$B$7*Assumptions!$B$4,0) | ... Y5: =IF('User Growth'!Y2="IN-SEASON",'User Growth'!Y19*Assumptions!$B$7*Assumptions!$B$4,0)
A6: Commissioner Annual Billing | B6: ='User Growth'!B19*Assumptions!$B$6*Assumptions!$B$4 | C6: ='User Growth'!C19*Assumptions!$B$6*Assumptions!$B$4 | D6: ='User Growth'!D19*Assumptions!$B$6*Assumptions!$B$4 | E6: ='User Growth'!E19*Assumptions!$B$6*Assumptions!$B$4 | F6: ='User Growth'!F19*Assumptions!$B$6*Assumptions!$B$4 | G6: ='User Growth'!G19*Assumptions!$B$6*Assumptions!$B$4 | H6: ='User Growth'!H19*Assumptions!$B$6*Assumptions!$B$4 | I6: ='User Growth'!I19*Assumptions!$B$6*Assumptions!$B$4 | ... Y6: ='User Growth'!Y19*Assumptions!$B$6*Assumptions!$B$4
A7: Gross Subscription Revenue | B7: =B3+B4+B5+B6 | C7: =C3+C4+C5+C6 | D7: =D3+D4+D5+D6 | E7: =E3+E4+E5+E6 | F7: =F3+F4+F5+F6 | G7: =G3+G4+G5+G6 | H7: =H3+H4+H5+H6 | I7: =I3+I4+I5+I6 | ... Y7: =Y3+Y4+Y5+Y6
A8: Less: Annual Billing Discount | B8: =-(B4+B6)*Assumptions!$B$5 | C8: =-(C4+C6)*Assumptions!$B$5 | D8: =-(D4+D6)*Assumptions!$B$5 | E8: =-(E4+E6)*Assumptions!$B$5 | F8: =-(F4+F6)*Assumptions!$B$5 | G8: =-(G4+G6)*Assumptions!$B$5 | H8: =-(H4+H6)*Assumptions!$B$5 | I8: =-(I4+I6)*Assumptions!$B$5 | ... Y8: =-(Y4+Y6)*Assumptions!$B$5
A9: NET SUBSCRIPTION REVENUE | B9: =B7+B8 | C9: =C7+C8 | D9: =D7+D8 | E9: =E7+E8 | F9: =F7+F8 | G9: =G7+G8 | H9: =H7+H8 | I9: =I7+I8 | ... Y9: =Y7+Y8
A11: PAY-PER-USE REVENUE
A12: Token Top-Ups (Free @ $2.99) | B12: ='User Growth'!B17*Assumptions!$B$34*Assumptions!$B$32 | C12: ='User Growth'!C17*Assumptions!$B$34*Assumptions!$B$32 | D12: ='User Growth'!D17*Assumptions!$B$34*Assumptions!$B$32 | E12: ='User Growth'!E17*Assumptions!$B$34*Assumptions!$B$32 | F12: ='User Growth'!F17*Assumptions!$B$34*Assumptions!$B$32 | G12: ='User Growth'!G17*Assumptions!$B$34*Assumptions!$B$32 | H12: ='User Growth'!H17*Assumptions!$B$34*Assumptions!$B$32 | I12: ='User Growth'!I17*Assumptions!$B$34*Assumptions!$B$32 | ... Y12: ='User Growth'!Y17*Assumptions!$B$34*Assumptions!$B$32
A13: Token Top-Ups (Paid @ $1.99) | B13: =('User Growth'!B18+'User Growth'!B19)*Assumptions!$B$35*Assumptions!$B$33 | C13: =('User Growth'!C18+'User Growth'!C19)*Assumptions!$B$35*Assumptions!$B$33 | D13: =('User Growth'!D18+'User Growth'!D19)*Assumptions!$B$35*Assumptions!$B$33 | E13: =('User Growth'!E18+'User Growth'!E19)*Assumptions!$B$35*Assumptions!$B$33 | F13: =('User Growth'!F18+'User Growth'!F19)*Assumptions!$B$35*Assumptions!$B$33 | G13: =('User Growth'!G18+'User Growth'!G19)*Assumptions!$B$35*Assumptions!$B$33 | H13: =('User Growth'!H18+'User Growth'!H19)*Assumptions!$B$35*Assumptions!$B$33 | I13: =('User Growth'!I18+'User Growth'!I19)*Assumptions!$B$35*Assumptions!$B$33 | ... Y13: =('User Growth'!Y18+'User Growth'!Y19)*Assumptions!$B$35*Assumptions!$B$33
A14: Draft Kits (Seasonal) | B14: =IF(OR(COLUMN()=7,COLUMN()=8,COLUMN()=19,COLUMN()=20),'User Growth'!B20*Assumptions!$B$37*Assumptions!$B$36,0) | C14: =IF(OR(COLUMN()=7,COLUMN()=8,COLUMN()=19,COLUMN()=20),'User Growth'!C20*Assumptions!$B$37*Assumptions!$B$36,0) | D14: =IF(OR(COLUMN()=7,COLUMN()=8,COLUMN()=19,COLUMN()=20),'User Growth'!D20*Assumptions!$B$37*Assumptions!$B$36,0) | E14: =IF(OR(COLUMN()=7,COLUMN()=8,COLUMN()=19,COLUMN()=20),'User Growth'!E20*Assumptions!$B$37*Assumptions!$B$36,0) | F14: =IF(OR(COLUMN()=7,COLUMN()=8,COLUMN()=19,COLUMN()=20),'User Growth'!F20*Assumptions!$B$37*Assumptions!$B$36,0) | G14: =IF(OR(COLUMN()=7,COLUMN()=8,COLUMN()=19,COLUMN()=20),'User Growth'!G20*Assumptions!$B$37*Assumptions!$B$36,0) | H14: =IF(OR(COLUMN()=7,COLUMN()=8,COLUMN()=19,COLUMN()=20),'User Growth'!H20*Assumptions!$B$37*Assumptions!$B$36,0) | I14: =IF(OR(COLUMN()=7,COLUMN()=8,COLUMN()=19,COLUMN()=20),'User Growth'!I20*Assumptions!$B$37*Assumptions!$B$36,0) | ... Y14: =IF(OR(COLUMN()=7,COLUMN()=8,COLUMN()=19,COLUMN()=20),'User Growth'!Y20*Assumptions!$B$37*Assumptions!$B$36,0)
A15: NET PAY-PER-USE REVENUE | B15: =B12+B13+B14 | C15: =C12+C13+C14 | D15: =D12+D13+D14 | E15: =E12+E13+E14 | F15: =F12+F13+F14 | G15: =G12+G13+G14 | H15: =H12+H13+H14 | I15: =I12+I13+I14 | ... Y15: =Y12+Y13+Y14
A17: DFS REVENUE
A18: Gross DFS Entry Fees (info) | B18: =IF(AND(COLUMN()-2>=Assumptions!$B$44,'User Growth'!B2="IN-SEASON"),'User Growth'!B20*Assumptions!$B$42*Assumptions!$B$43*Assumptions!$B$41,0) | C18: =IF(AND(COLUMN()-2>=Assumptions!$B$44,'User Growth'!C2="IN-SEASON"),'User Growth'!C20*Assumptions!$B$42*Assumptions!$B$43*Assumptions!$B$41,0) | D18: =IF(AND(COLUMN()-2>=Assumptions!$B$44,'User Growth'!D2="IN-SEASON"),'User Growth'!D20*Assumptions!$B$42*Assumptions!$B$43*Assumptions!$B$41,0) | E18: =IF(AND(COLUMN()-2>=Assumptions!$B$44,'User Growth'!E2="IN-SEASON"),'User Growth'!E20*Assumptions!$B$42*Assumptions!$B$43*Assumptions!$B$41,0) | F18: =IF(AND(COLUMN()-2>=Assumptions!$B$44,'User Growth'!F2="IN-SEASON"),'User Growth'!F20*Assumptions!$B$42*Assumptions!$B$43*Assumptions!$B$41,0) | G18: =IF(AND(COLUMN()-2>=Assumptions!$B$44,'User Growth'!G2="IN-SEASON"),'User Growth'!G20*Assumptions!$B$42*Assumptions!$B$43*Assumptions!$B$41,0) | H18: =IF(AND(COLUMN()-2>=Assumptions!$B$44,'User Growth'!H2="IN-SEASON"),'User Growth'!H20*Assumptions!$B$42*Assumptions!$B$43*Assumptions!$B$41,0) | I18: =IF(AND(COLUMN()-2>=Assumptions!$B$44,'User Growth'!I2="IN-SEASON"),'User Growth'!I20*Assumptions!$B$42*Assumptions!$B$43*Assumptions!$B$41,0) | ... Y18: =IF(AND(COLUMN()-2>=Assumptions!$B$44,'User Growth'!Y2="IN-SEASON"),'User Growth'!Y20*Assumptions!$B$42*Assumptions!$B$43*Assumptions!$B$41,0)
A19: DFS Rake Revenue | B19: =B18*Assumptions!$B$40 | C19: =C18*Assumptions!$B$40 | D19: =D18*Assumptions!$B$40 | E19: =E18*Assumptions!$B$40 | F19: =F18*Assumptions!$B$40 | G19: =G18*Assumptions!$B$40 | H19: =H18*Assumptions!$B$40 | I19: =I18*Assumptions!$B$40 | ... Y19: =Y18*Assumptions!$B$40
A20: NET DFS REVENUE | B20: =B19 | C20: =C19 | D20: =D19 | E20: =E19 | F20: =F19 | G20: =G19 | H20: =H19 | I20: =I19 | ... Y20: =Y19
A22: ADVERTISING REVENUE
A23: Ad Impressions (000s) | B23: ='User Growth'!B17*IF('User Growth'!B2="IN-SEASON",Assumptions!$B$48,Assumptions!$B$49)*Assumptions!$B$50/1000 | C23: ='User Growth'!C17*IF('User Growth'!C2="IN-SEASON",Assumptions!$B$48,Assumptions!$B$49)*Assumptions!$B$50/1000 | D23: ='User Growth'!D17*IF('User Growth'!D2="IN-SEASON",Assumptions!$B$48,Assumptions!$B$49)*Assumptions!$B$50/1000 | E23: ='User Growth'!E17*IF('User Growth'!E2="IN-SEASON",Assumptions!$B$48,Assumptions!$B$49)*Assumptions!$B$50/1000 | F23: ='User Growth'!F17*IF('User Growth'!F2="IN-SEASON",Assumptions!$B$48,Assumptions!$B$49)*Assumptions!$B$50/1000 | G23: ='User Growth'!G17*IF('User Growth'!G2="IN-SEASON",Assumptions!$B$48,Assumptions!$B$49)*Assumptions!$B$50/1000 | H23: ='User Growth'!H17*IF('User Growth'!H2="IN-SEASON",Assumptions!$B$48,Assumptions!$B$49)*Assumptions!$B$50/1000 | I23: ='User Growth'!I17*IF('User Growth'!I2="IN-SEASON",Assumptions!$B$48,Assumptions!$B$49)*Assumptions!$B$50/1000 | ... Y23: ='User Growth'!Y17*IF('User Growth'!Y2="IN-SEASON",Assumptions!$B$48,Assumptions!$B$49)*Assumptions!$B$50/1000
A24: Ad Revenue | B24: =B23*Assumptions!$B$47 | C24: =C23*Assumptions!$B$47 | D24: =D23*Assumptions!$B$47 | E24: =E23*Assumptions!$B$47 | F24: =F23*Assumptions!$B$47 | G24: =G23*Assumptions!$B$47 | H24: =H23*Assumptions!$B$47 | I24: =I23*Assumptions!$B$47 | ... Y24: =Y23*Assumptions!$B$47
A25: NET ADVERTISING REVENUE | B25: =B24 | C25: =C24 | D25: =D24 | E25: =E24 | F25: =F24 | G25: =G24 | H25: =H24 | I25: =I24 | ... Y25: =Y24
A27: GROSS REVENUE | B27: =B9+B15+B20+B25 | C27: =C9+C15+C20+C25 | D27: =D9+D15+D20+D25 | E27: =E9+E15+E20+E25 | F27: =F9+F15+F20+F25 | G27: =G9+G15+G20+G25 | H27: =H9+H15+H20+H25 | I27: =I9+I15+I20+I25 | ... Y27: =Y9+Y15+Y20+Y25
A29: PLATFORM FEES
A30: Apple App Store (15%) | B30: =B9*Assumptions!$B$69*Assumptions!$B$67*Assumptions!$B$63 | C30: =C9*Assumptions!$B$69*Assumptions!$B$67*Assumptions!$B$63 | D30: =D9*Assumptions!$B$69*Assumptions!$B$67*Assumptions!$B$63 | E30: =E9*Assumptions!$B$69*Assumptions!$B$67*Assumptions!$B$63 | F30: =F9*Assumptions!$B$69*Assumptions!$B$67*Assumptions!$B$63 | G30: =G9*Assumptions!$B$69*Assumptions!$B$67*Assumptions!$B$63 | H30: =H9*Assumptions!$B$69*Assumptions!$B$67*Assumptions!$B$63 | I30: =I9*Assumptions!$B$69*Assumptions!$B$67*Assumptions!$B$63 | ... Y30: =Y9*Assumptions!$B$69*Assumptions!$B$67*Assumptions!$B$63
A31: Google Play (15%) | B31: =B9*Assumptions!$B$69*Assumptions!$B$68*Assumptions!$B$64 | C31: =C9*Assumptions!$B$69*Assumptions!$B$68*Assumptions!$B$64 | D31: =D9*Assumptions!$B$69*Assumptions!$B$68*Assumptions!$B$64 | E31: =E9*Assumptions!$B$69*Assumptions!$B$68*Assumptions!$B$64 | F31: =F9*Assumptions!$B$69*Assumptions!$B$68*Assumptions!$B$64 | G31: =G9*Assumptions!$B$69*Assumptions!$B$68*Assumptions!$B$64 | H31: =H9*Assumptions!$B$69*Assumptions!$B$68*Assumptions!$B$64 | I31: =I9*Assumptions!$B$69*Assumptions!$B$68*Assumptions!$B$64 | ... Y31: =Y9*Assumptions!$B$69*Assumptions!$B$68*Assumptions!$B$64
A32: Stripe Processing | B32: =IF((B9*(1-Assumptions!$B$69)+B15+B20)>0,(B9*(1-Assumptions!$B$69)+B15+B20)*Assumptions!$B$65+MAX(1,('User Growth'!B18+'User Growth'!B19)*0.3+'User Growth'!B17*Assumptions!$B$34+('User Growth'!B18+'User Growth'!B19)*Assumptions!$B$35)*Assumptions!$B$66,0) | C32: =IF((C9*(1-Assumptions!$B$69)+C15+C20)>0,(C9*(1-Assumptions!$B$69)+C15+C20)*Assumptions!$B$65+MAX(1,('User Growth'!C18+'User Growth'!C19)*0.3+'User Growth'!C17*Assumptions!$B$34+('User Growth'!C18+'User Growth'!C19)*Assumptions!$B$35)*Assumptions!$B$66,0) | D32: =IF((D9*(1-Assumptions!$B$69)+D15+D20)>0,(D9*(1-Assumptions!$B$69)+D15+D20)*Assumptions!$B$65+MAX(1,('User Growth'!D18+'User Growth'!D19)*0.3+'User Growth'!D17*Assumptions!$B$34+('User Growth'!D18+'User Growth'!D19)*Assumptions!$B$35)*Assumptions!$B$66,0) | E32: =IF((E9*(1-Assumptions!$B$69)+E15+E20)>0,(E9*(1-Assumptions!$B$69)+E15+E20)*Assumptions!$B$65+MAX(1,('User Growth'!E18+'User Growth'!E19)*0.3+'User Growth'!E17*Assumptions!$B$34+('User Growth'!E18+'User Growth'!E19)*Assumptions!$B$35)*Assumptions!$B$66,0) | F32: =IF((F9*(1-Assumptions!$B$69)+F15+F20)>0,(F9*(1-Assumptions!$B$69)+F15+F20)*Assumptions!$B$65+MAX(1,('User Growth'!F18+'User Growth'!F19)*0.3+'User Growth'!F17*Assumptions!$B$34+('User Growth'!F18+'User Growth'!F19)*Assumptions!$B$35)*Assumptions!$B$66,0) | G32: =IF((G9*(1-Assumptions!$B$69)+G15+G20)>0,(G9*(1-Assumptions!$B$69)+G15+G20)*Assumptions!$B$65+MAX(1,('User Growth'!G18+'User Growth'!G19)*0.3+'User Growth'!G17*Assumptions!$B$34+('User Growth'!G18+'User Growth'!G19)*Assumptions!$B$35)*Assumptions!$B$66,0) | H32: =IF((H9*(1-Assumptions!$B$69)+H15+H20)>0,(H9*(1-Assumptions!$B$69)+H15+H20)*Assumptions!$B$65+MAX(1,('User Growth'!H18+'User Growth'!H19)*0.3+'User Growth'!H17*Assumptions!$B$34+('User Growth'!H18+'User Growth'!H19)*Assumptions!$B$35)*Assumptions!$B$66,0) | I32: =IF((I9*(1-Assumptions!$B$69)+I15+I20)>0,(I9*(1-Assumptions!$B$69)+I15+I20)*Assumptions!$B$65+MAX(1,('User Growth'!I18+'User Growth'!I19)*0.3+'User Growth'!I17*Assumptions!$B$34+('User Growth'!I18+'User Growth'!I19)*Assumptions!$B$35)*Assumptions!$B$66,0) | ... Y32: =IF((Y9*(1-Assumptions!$B$69)+Y15+Y20)>0,(Y9*(1-Assumptions!$B$69)+Y15+Y20)*Assumptions!$B$65+MAX(1,('User Growth'!Y18+'User Growth'!Y19)*0.3+'User Growth'!Y17*Assumptions!$B$34+('User Growth'!Y18+'User Growth'!Y19)*Assumptions!$B$35)*Assumptions!$B$66,0)
A33: Total Platform Fees | B33: =B30+B31+B32 | C33: =C30+C31+C32 | D33: =D30+D31+D32 | E33: =E30+E31+E32 | F33: =F30+F31+F32 | G33: =G30+G31+G32 | H33: =H30+H31+H32 | I33: =I30+I31+I32 | ... Y33: =Y30+Y31+Y32
A35: NET REVENUE | B35: =B27-B33 | C35: =C27-C33 | D35: =D27-D33 | E35: =E27-E33 | F35: =F27-F33 | G35: =G27-G33 | H35: =H27-H33 | I35: =I27-I33 | ... Y35: =Y27-Y33
A37: REVENUE MIX (% of Gross)
A38: Subscription % | B38: =IF(B27>0,B9/B27,0) | C38: =IF(C27>0,C9/C27,0) | D38: =IF(D27>0,D9/D27,0) | E38: =IF(E27>0,E9/E27,0) | F38: =IF(F27>0,F9/F27,0) | G38: =IF(G27>0,G9/G27,0) | H38: =IF(H27>0,H9/H27,0) | I38: =IF(I27>0,I9/I27,0) | ... Y38: =IF(Y27>0,Y9/Y27,0)
A39: Pay-Per-Use % | B39: =IF(B27>0,B15/B27,0) | C39: =IF(C27>0,C15/C27,0) | D39: =IF(D27>0,D15/D27,0) | E39: =IF(E27>0,E15/E27,0) | F39: =IF(F27>0,F15/F27,0) | G39: =IF(G27>0,G15/G27,0) | H39: =IF(H27>0,H15/H27,0) | I39: =IF(I27>0,I15/I27,0) | ... Y39: =IF(Y27>0,Y15/Y27,0)
A40: DFS % | B40: =IF(B27>0,B20/B27,0) | C40: =IF(C27>0,C20/C27,0) | D40: =IF(D27>0,D20/D27,0) | E40: =IF(E27>0,E20/E27,0) | F40: =IF(F27>0,F20/F27,0) | G40: =IF(G27>0,G20/G27,0) | H40: =IF(H27>0,H20/H27,0) | I40: =IF(I27>0,I20/I27,0) | ... Y40: =IF(Y27>0,Y20/Y27,0)
A41: Advertising % | B41: =IF(B27>0,B25/B27,0) | C41: =IF(C27>0,C25/C27,0) | D41: =IF(D27>0,D25/D27,0) | E41: =IF(E27>0,E25/E27,0) | F41: =IF(F27>0,F25/F27,0) | G41: =IF(G27>0,G25/G27,0) | H41: =IF(H27>0,H25/H27,0) | I41: =IF(I27>0,I25/I27,0) | ... Y41: =IF(Y27>0,Y25/Y27,0)
A43: MRR (Subscription Only) | B43: =B9 | C43: =C9 | D43: =D9 | E43: =E9 | F43: =F9 | G43: =G9 | H43: =H9 | I43: =I9 | ... Y43: =Y9
A44: ARR (= MRR x 12) | B44: =B9*12 | C44: =C9*12 | D44: =D9*12 | E44: =E9*12 | F44: =F9*12 | G44: =G9*12 | H44: =H9*12 | I44: =I9*12 | ... Y44: =Y9*12
A45: Cumulative Net Revenue | B45: =B35 | C45: =B45+C35 | D45: =C45+D35 | E45: =D45+E35 | F45: =E45+F35 | G45: =F45+G35 | H45: =G45+H35 | I45: =H45+I35 | J45: =I45+J35 | ... Y45: =X45+Y35

Sheet COGS & Operating Expenses
A1: Cost Line | B1: Apr-26 | C1: May-26 | D1: Jun-26 | E1: Jul-26 | F1: Aug-26 | G1: Sep-26 | H1: Oct-26 | I1: Nov-26 | J1: Dec-26 | K1: Jan-27 | L1: Feb-27 | M1: Mar-27 | N1: Apr-27 | O1: May-27 | P1: Jun-27 | Q1: Jul-27 | R1: Aug-27 | S1: Sep-27 | T1: Oct-27 | U1: Nov-27 | V1: Dec-27 | W1: Jan-28 | X1: Feb-28 | Y1: Mar-28
A2: COST OF GOODS SOLD (COGS)
A3: Supabase (Database + Auth) | B3: =IF('User Growth'!B20>Assumptions!$B$55,Assumptions!$B$54,Assumptions!$B$53) | C3: =IF('User Growth'!C20>Assumptions!$B$55,Assumptions!$B$54,Assumptions!$B$53) | D3: =IF('User Growth'!D20>Assumptions!$B$55,Assumptions!$B$54,Assumptions!$B$53) | E3: =IF('User Growth'!E20>Assumptions!$B$55,Assumptions!$B$54,Assumptions!$B$53) | F3: =IF('User Growth'!F20>Assumptions!$B$55,Assumptions!$B$54,Assumptions!$B$53) | G3: =IF('User Growth'!G20>Assumptions!$B$55,Assumptions!$B$54,Assumptions!$B$53) | H3: =IF('User Growth'!H20>Assumptions!$B$55,Assumptions!$B$54,Assumptions!$B$53) | I3: =IF('User Growth'!I20>Assumptions!$B$55,Assumptions!$B$54,Assumptions!$B$53) | ... Y3: =IF('User Growth'!Y20>Assumptions!$B$55,Assumptions!$B$54,Assumptions!$B$53)
A4: Firebase Hosting | B4: =Assumptions!$B$56+MAX(0,'User Growth'!B20-1000)*Assumptions!$B$57 | C4: =Assumptions!$B$56+MAX(0,'User Growth'!C20-1000)*Assumptions!$B$57 | D4: =Assumptions!$B$56+MAX(0,'User Growth'!D20-1000)*Assumptions!$B$57 | E4: =Assumptions!$B$56+MAX(0,'User Growth'!E20-1000)*Assumptions!$B$57 | F4: =Assumptions!$B$56+MAX(0,'User Growth'!F20-1000)*Assumptions!$B$57 | G4: =Assumptions!$B$56+MAX(0,'User Growth'!G20-1000)*Assumptions!$B$57 | H4: =Assumptions!$B$56+MAX(0,'User Growth'!H20-1000)*Assumptions!$B$57 | I4: =Assumptions!$B$56+MAX(0,'User Growth'!I20-1000)*Assumptions!$B$57 | ... Y4: =Assumptions!$B$56+MAX(0,'User Growth'!Y20-1000)*Assumptions!$B$57
A5: Claude API (Stormy AI) | B5: =('User Growth'!B17*Assumptions!$B$27+'User Growth'!B18*Assumptions!$B$28+'User Growth'!B19*Assumptions!$B$29)/1000000*Assumptions!$B$58 | C5: =('User Growth'!C17*Assumptions!$B$27+'User Growth'!C18*Assumptions!$B$28+'User Growth'!C19*Assumptions!$B$29)/1000000*Assumptions!$B$58 | D5: =('User Growth'!D17*Assumptions!$B$27+'User Growth'!D18*Assumptions!$B$28+'User Growth'!D19*Assumptions!$B$29)/1000000*Assumptions!$B$58 | E5: =('User Growth'!E17*Assumptions!$B$27+'User Growth'!E18*Assumptions!$B$28+'User Growth'!E19*Assumptions!$B$29)/1000000*Assumptions!$B$58 | F5: =('User Growth'!F17*Assumptions!$B$27+'User Growth'!F18*Assumptions!$B$28+'User Growth'!F19*Assumptions!$B$29)/1000000*Assumptions!$B$58 | G5: =('User Growth'!G17*Assumptions!$B$27+'User Growth'!G18*Assumptions!$B$28+'User Growth'!G19*Assumptions!$B$29)/1000000*Assumptions!$B$58 | H5: =('User Growth'!H17*Assumptions!$B$27+'User Growth'!H18*Assumptions!$B$28+'User Growth'!H19*Assumptions!$B$29)/1000000*Assumptions!$B$58 | I5: =('User Growth'!I17*Assumptions!$B$27+'User Growth'!I18*Assumptions!$B$28+'User Growth'!I19*Assumptions!$B$29)/1000000*Assumptions!$B$58 | ... Y5: =('User Growth'!Y17*Assumptions!$B$27+'User Growth'!Y18*Assumptions!$B$28+'User Growth'!Y19*Assumptions!$B$29)/1000000*Assumptions!$B$58
A6: Proxy Rotation (Data Pipeline) | B6: =Assumptions!$B$59 | C6: =Assumptions!$B$59 | D6: =Assumptions!$B$59 | E6: =Assumptions!$B$59 | F6: =Assumptions!$B$59 | G6: =Assumptions!$B$59 | H6: =Assumptions!$B$59 | I6: =Assumptions!$B$59 | ... Y6: =Assumptions!$B$59
A7: Domain / SSL / Misc | B7: =Assumptions!$B$60 | C7: =Assumptions!$B$60 | D7: =Assumptions!$B$60 | E7: =Assumptions!$B$60 | F7: =Assumptions!$B$60 | G7: =Assumptions!$B$60 | H7: =Assumptions!$B$60 | I7: =Assumptions!$B$60 | ... Y7: =Assumptions!$B$60
A8: TOTAL COGS | B8: =B3+B4+B5+B6+B7 | C8: =C3+C4+C5+C6+C7 | D8: =D3+D4+D5+D6+D7 | E8: =E3+E4+E5+E6+E7 | F8: =F3+F4+F5+F6+F7 | G8: =G3+G4+G5+G6+G7 | H8: =H3+H4+H5+H6+H7 | I8: =I3+I4+I5+I6+I7 | ... Y8: =Y3+Y4+Y5+Y6+Y7
A10: GROSS PROFIT | B10: =Revenue!B35-B8 | C10: =Revenue!C35-C8 | D10: =Revenue!D35-D8 | E10: =Revenue!E35-E8 | F10: =Revenue!F35-F8 | G10: =Revenue!G35-G8 | H10: =Revenue!H35-H8 | I10: =Revenue!I35-I8 | ... Y10: =Revenue!Y35-Y8
A11: GROSS MARGIN % | B11: =IF(Revenue!B35<>0,B10/Revenue!B35,0) | C11: =IF(Revenue!C35<>0,C10/Revenue!C35,0) | D11: =IF(Revenue!D35<>0,D10/Revenue!D35,0) | E11: =IF(Revenue!E35<>0,E10/Revenue!E35,0) | F11: =IF(Revenue!F35<>0,F10/Revenue!F35,0) | G11: =IF(Revenue!G35<>0,G10/Revenue!G35,0) | H11: =IF(Revenue!H35<>0,H10/Revenue!H35,0) | I11: =IF(Revenue!I35<>0,I10/Revenue!I35,0) | ... Y11: =IF(Revenue!Y35<>0,Y10/Revenue!Y35,0)
A13: OPERATING EXPENSES (OPEX)
A14: SALES & MARKETING
A15: Digital Marketing | B15: =IF(COLUMN()-2>=Assumptions!$B$74,'User Growth'!B3*Assumptions!$B$75,0) | C15: =IF(COLUMN()-2>=Assumptions!$B$74,'User Growth'!C3*Assumptions!$B$75,0) | D15: =IF(COLUMN()-2>=Assumptions!$B$74,'User Growth'!D3*Assumptions!$B$75,0) | E15: =IF(COLUMN()-2>=Assumptions!$B$74,'User Growth'!E3*Assumptions!$B$75,0) | F15: =IF(COLUMN()-2>=Assumptions!$B$74,'User Growth'!F3*Assumptions!$B$75,0) | G15: =IF(COLUMN()-2>=Assumptions!$B$74,'User Growth'!G3*Assumptions!$B$75,0) | H15: =IF(COLUMN()-2>=Assumptions!$B$74,'User Growth'!H3*Assumptions!$B$75,0) | I15: =IF(COLUMN()-2>=Assumptions!$B$74,'User Growth'!I3*Assumptions!$B$75,0) | ... Y15: =IF(COLUMN()-2>=Assumptions!$B$74,'User Growth'!Y3*Assumptions!$B$75,0)
A16: Influencer / Content Marketing | B16: =Assumptions!$B$78 | C16: =Assumptions!$B$79 | D16: =Assumptions!$B$80 | E16: =Assumptions!$B$81 | F16: =Assumptions!$B$82 | G16: =Assumptions!$B$83 | H16: =Assumptions!$B$84 | I16: =Assumptions!$B$85 | J16: =Assumptions!$B$86 | K16: =Assumptions!$B$87 | L16: =Assumptions!$B$88 | M16: =Assumptions!$B$89 | N16: =Assumptions!$B$90 | O16: =Assumptions!$B$91 | P16: =Assumptions!$B$92 | Q16: =Assumptions!$B$93 | R16: =Assumptions!$B$94 | S16: =Assumptions!$B$95 | T16: =Assumptions!$B$96 | U16: =Assumptions!$B$97 | V16: =Assumptions!$B$98 | W16: =Assumptions!$B$99 | X16: =Assumptions!$B$100 | Y16: =Assumptions!$B$101
A17: Total Sales & Marketing | B17: =B15+B16 | C17: =C15+C16 | D17: =D15+D16 | E17: =E15+E16 | F17: =F15+F16 | G17: =G15+G16 | H17: =H15+H16 | I17: =I15+I16 | ... Y17: =Y15+Y16
A19: GENERAL & ADMINISTRATIVE
A20: Contractors / Team | B20: =IF(COLUMN()-2<6,Assumptions!$B$104,IF(COLUMN()-2<12,Assumptions!$B$105,IF(COLUMN()-2<18,Assumptions!$B$106,Assumptions!$B$107))) | C20: =IF(COLUMN()-2<6,Assumptions!$B$104,IF(COLUMN()-2<12,Assumptions!$B$105,IF(COLUMN()-2<18,Assumptions!$B$106,Assumptions!$B$107))) | D20: =IF(COLUMN()-2<6,Assumptions!$B$104,IF(COLUMN()-2<12,Assumptions!$B$105,IF(COLUMN()-2<18,Assumptions!$B$106,Assumptions!$B$107))) | E20: =IF(COLUMN()-2<6,Assumptions!$B$104,IF(COLUMN()-2<12,Assumptions!$B$105,IF(COLUMN()-2<18,Assumptions!$B$106,Assumptions!$B$107))) | F20: =IF(COLUMN()-2<6,Assumptions!$B$104,IF(COLUMN()-2<12,Assumptions!$B$105,IF(COLUMN()-2<18,Assumptions!$B$106,Assumptions!$B$107))) | G20: =IF(COLUMN()-2<6,Assumptions!$B$104,IF(COLUMN()-2<12,Assumptions!$B$105,IF(COLUMN()-2<18,Assumptions!$B$106,Assumptions!$B$107))) | H20: =IF(COLUMN()-2<6,Assumptions!$B$104,IF(COLUMN()-2<12,Assumptions!$B$105,IF(COLUMN()-2<18,Assumptions!$B$106,Assumptions!$B$107))) | I20: =IF(COLUMN()-2<6,Assumptions!$B$104,IF(COLUMN()-2<12,Assumptions!$B$105,IF(COLUMN()-2<18,Assumptions!$B$106,Assumptions!$B$107))) | ... Y20: =IF(COLUMN()-2<6,Assumptions!$B$104,IF(COLUMN()-2<12,Assumptions!$B$105,IF(COLUMN()-2<18,Assumptions!$B$106,Assumptions!$B$107)))
A21: Legal & Accounting (Basic) | B21: =IF(COLUMN()<14,Assumptions!$B$110,Assumptions!$B$111) | C21: =IF(COLUMN()<14,Assumptions!$B$110,Assumptions!$B$111) | D21: =IF(COLUMN()<14,Assumptions!$B$110,Assumptions!$B$111) | E21: =IF(COLUMN()<14,Assumptions!$B$110,Assumptions!$B$111) | F21: =IF(COLUMN()<14,Assumptions!$B$110,Assumptions!$B$111) | G21: =IF(COLUMN()<14,Assumptions!$B$110,Assumptions!$B$111) | H21: =IF(COLUMN()<14,Assumptions!$B$110,Assumptions!$B$111) | I21: =IF(COLUMN()<14,Assumptions!$B$110,Assumptions!$B$111) | ... Y21: =IF(COLUMN()<14,Assumptions!$B$110,Assumptions!$B$111)
A22: DFS Regulatory — Canada | B22: =IF('User Growth'!B20>=Assumptions!$B$114,Assumptions!$B$115+Assumptions!$B$116+Assumptions!$B$117+Assumptions!$B$118,0) | C22: =IF('User Growth'!C20>=Assumptions!$B$114,Assumptions!$B$115+Assumptions!$B$116+Assumptions!$B$117+Assumptions!$B$118,0) | D22: =IF('User Growth'!D20>=Assumptions!$B$114,Assumptions!$B$115+Assumptions!$B$116+Assumptions!$B$117+Assumptions!$B$118,0) | E22: =IF('User Growth'!E20>=Assumptions!$B$114,Assumptions!$B$115+Assumptions!$B$116+Assumptions!$B$117+Assumptions!$B$118,0) | F22: =IF('User Growth'!F20>=Assumptions!$B$114,Assumptions!$B$115+Assumptions!$B$116+Assumptions!$B$117+Assumptions!$B$118,0) | G22: =IF('User Growth'!G20>=Assumptions!$B$114,Assumptions!$B$115+Assumptions!$B$116+Assumptions!$B$117+Assumptions!$B$118,0) | H22: =IF('User Growth'!H20>=Assumptions!$B$114,Assumptions!$B$115+Assumptions!$B$116+Assumptions!$B$117+Assumptions!$B$118,0) | I22: =IF('User Growth'!I20>=Assumptions!$B$114,Assumptions!$B$115+Assumptions!$B$116+Assumptions!$B$117+Assumptions!$B$118,0) | ... Y22: =IF('User Growth'!Y20>=Assumptions!$B$114,Assumptions!$B$115+Assumptions!$B$116+Assumptions!$B$117+Assumptions!$B$118,0)
A23: US DFS Licensing (State-by-State) | B23: =IF(COLUMN()-2>=Assumptions!$B$121,IF(COLUMN()-2-Assumptions!$B$121<12,Assumptions!$B$124/12+Assumptions!$B$126/12+Assumptions!$B$128/12+Assumptions!$B$130/12+Assumptions!$B$132/12+Assumptions!$B$134/12+Assumptions!$B$136/12+Assumptions!$B$138/12+Assumptions!$B$140/12+Assumptions!$B$142/12+Assumptions!$B$144/12+Assumptions!$B$146/12+Assumptions!$B$148/12+Assumptions!$B$150/12+Assumptions!$B$152/12+Assumptions!$B$154/12+Assumptions!$B$156/12+Assumptions!$B$158/12+Assumptions!$B$160/12,Assumptions!$B$125/12+Assumptions!$B$127/12+Assumptions!$B$129/12+Assumptions!$B$131/12+Assumptions!$B$133/12+Assumptions!$B$135/12+Assumptions!$B$137/12+Assumptions!$B$139/12+Assumptions!$B$141/12+Assumptions!$B$143/12+Assumptions!$B$145/12+Assumptions!$B$147/12+Assumptions!$B$149/12+Assumptions!$B$151/12+Assumptions!$B$153/12+Assumptions!$B$155/12+Assumptions!$B$157/12+Assumptions!$B$159/12+Assumptions!$B$161/12),0) | C23: =IF(COLUMN()-2>=Assumptions!$B$121,IF(COLUMN()-2-Assumptions!$B$121<12,Assumptions!$B$124/12+Assumptions!$B$126/12+Assumptions!$B$128/12+Assumptions!$B$130/12+Assumptions!$B$132/12+Assumptions!$B$134/12+Assumptions!$B$136/12+Assumptions!$B$138/12+Assumptions!$B$140/12+Assumptions!$B$142/12+Assumptions!$B$144/12+Assumptions!$B$146/12+Assumptions!$B$148/12+Assumptions!$B$150/12+Assumptions!$B$152/12+Assumptions!$B$154/12+Assumptions!$B$156/12+Assumptions!$B$158/12+Assumptions!$B$160/12,Assumptions!$B$125/12+Assumptions!$B$127/12+Assumptions!$B$129/12+Assumptions!$B$131/12+Assumptions!$B$133/12+Assumptions!$B$135/12+Assumptions!$B$137/12+Assumptions!$B$139/12+Assumptions!$B$141/12+Assumptions!$B$143/12+Assumptions!$B$145/12+Assumptions!$B$147/12+Assumptions!$B$149/12+Assumptions!$B$151/12+Assumptions!$B$153/12+Assumptions!$B$155/12+Assumptions!$B$157/12+Assumptions!$B$159/12+Assumptions!$B$161/12),0) | D23: =IF(COLUMN()-2>=Assumptions!$B$121,IF(COLUMN()-2-Assumptions!$B$121<12,Assumptions!$B$124/12+Assumptions!$B$126/12+Assumptions!$B$128/12+Assumptions!$B$130/12+Assumptions!$B$132/12+Assumptions!$B$134/12+Assumptions!$B$136/12+Assumptions!$B$138/12+Assumptions!$B$140/12+Assumptions!$B$142/12+Assumptions!$B$144/12+Assumptions!$B$146/12+Assumptions!$B$148/12+Assumptions!$B$150/12+Assumptions!$B$152/12+Assumptions!$B$154/12+Assumptions!$B$156/12+Assumptions!$B$158/12+Assumptions!$B$160/12,Assumptions!$B$125/12+Assumptions!$B$127/12+Assumptions!$B$129/12+Assumptions!$B$131/12+Assumptions!$B$133/12+Assumptions!$B$135/12+Assumptions!$B$137/12+Assumptions!$B$139/12+Assumptions!$B$141/12+Assumptions!$B$143/12+Assumptions!$B$145/12+Assumptions!$B$147/12+Assumptions!$B$149/12+Assumptions!$B$151/12+Assumptions!$B$153/12+Assumptions!$B$155/12+Assumptions!$B$157/12+Assumptions!$B$159/12+Assumptions!$B$161/12),0) | E23: =IF(COLUMN()-2>=Assumptions!$B$121,IF(COLUMN()-2-Assumptions!$B$121<12,Assumptions!$B$124/12+Assumptions!$B$126/12+Assumptions!$B$128/12+Assumptions!$B$130/12+Assumptions!$B$132/12+Assumptions!$B$134/12+Assumptions!$B$136/12+Assumptions!$B$138/12+Assumptions!$B$140/12+Assumptions!$B$142/12+Assumptions!$B$144/12+Assumptions!$B$146/12+Assumptions!$B$148/12+Assumptions!$B$150/12+Assumptions!$B$152/12+Assumptions!$B$154/12+Assumptions!$B$156/12+Assumptions!$B$158/12+Assumptions!$B$160/12,Assumptions!$B$125/12+Assumptions!$B$127/12+Assumptions!$B$129/12+Assumptions!$B$131/12+Assumptions!$B$133/12+Assumptions!$B$135/12+Assumptions!$B$137/12+Assumptions!$B$139/12+Assumptions!$B$141/12+Assumptions!$B$143/12+Assumptions!$B$145/12+Assumptions!$B$147/12+Assumptions!$B$149/12+Assumptions!$B$151/12+Assumptions!$B$153/12+Assumptions!$B$155/12+Assumptions!$B$157/12+Assumptions!$B$159/12+Assumptions!$B$161/12),0) | F23: =IF(COLUMN()-2>=Assumptions!$B$121,IF(COLUMN()-2-Assumptions!$B$121<12,Assumptions!$B$124/12+Assumptions!$B$126/12+Assumptions!$B$128/12+Assumptions!$B$130/12+Assumptions!$B$132/12+Assumptions!$B$134/12+Assumptions!$B$136/12+Assumptions!$B$138/12+Assumptions!$B$140/12+Assumptions!$B$142/12+Assumptions!$B$144/12+Assumptions!$B$146/12+Assumptions!$B$148/12+Assumptions!$B$150/12+Assumptions!$B$152/12+Assumptions!$B$154/12+Assumptions!$B$156/12+Assumptions!$B$158/12+Assumptions!$B$160/12,Assumptions!$B$125/12+Assumptions!$B$127/12+Assumptions!$B$129/12+Assumptions!$B$131/12+Assumptions!$B$133/12+Assumptions!$B$135/12+Assumptions!$B$137/12+Assumptions!$B$139/12+Assumptions!$B$141/12+Assumptions!$B$143/12+Assumptions!$B$145/12+Assumptions!$B$147/12+Assumptions!$B$149/12+Assumptions!$B$151/12+Assumptions!$B$153/12+Assumptions!$B$155/12+Assumptions!$B$157/12+Assumptions!$B$159/12+Assumptions!$B$161/12),0) | G23: =IF(COLUMN()-2>=Assumptions!$B$121,IF(COLUMN()-2-Assumptions!$B$121<12,Assumptions!$B$124/12+Assumptions!$B$126/12+Assumptions!$B$128/12+Assumptions!$B$130/12+Assumptions!$B$132/12+Assumptions!$B$134/12+Assumptions!$B$136/12+Assumptions!$B$138/12+Assumptions!$B$140/12+Assumptions!$B$142/12+Assumptions!$B$144/12+Assumptions!$B$146/12+Assumptions!$B$148/12+Assumptions!$B$150/12+Assumptions!$B$152/12+Assumptions!$B$154/12+Assumptions!$B$156/12+Assumptions!$B$158/12+Assumptions!$B$160/12,Assumptions!$B$125/12+Assumptions!$B$127/12+Assumptions!$B$129/12+Assumptions!$B$131/12+Assumptions!$B$133/12+Assumptions!$B$135/12+Assumptions!$B$137/12+Assumptions!$B$139/12+Assumptions!$B$141/12+Assumptions!$B$143/12+Assumptions!$B$145/12+Assumptions!$B$147/12+Assumptions!$B$149/12+Assumptions!$B$151/12+Assumptions!$B$153/12+Assumptions!$B$155/12+Assumptions!$B$157/12+Assumptions!$B$159/12+Assumptions!$B$161/12),0) | H23: =IF(COLUMN()-2>=Assumptions!$B$121,IF(COLUMN()-2-Assumptions!$B$121<12,Assumptions!$B$124/12+Assumptions!$B$126/12+Assumptions!$B$128/12+Assumptions!$B$130/12+Assumptions!$B$132/12+Assumptions!$B$134/12+Assumptions!$B$136/12+Assumptions!$B$138/12+Assumptions!$B$140/12+Assumptions!$B$142/12+Assumptions!$B$144/12+Assumptions!$B$146/12+Assumptions!$B$148/12+Assumptions!$B$150/12+Assumptions!$B$152/12+Assumptions!$B$154/12+Assumptions!$B$156/12+Assumptions!$B$158/12+Assumptions!$B$160/12,Assumptions!$B$125/12+Assumptions!$B$127/12+Assumptions!$B$129/12+Assumptions!$B$131/12+Assumptions!$B$133/12+Assumptions!$B$135/12+Assumptions!$B$137/12+Assumptions!$B$139/12+Assumptions!$B$141/12+Assumptions!$B$143/12+Assumptions!$B$145/12+Assumptions!$B$147/12+Assumptions!$B$149/12+Assumptions!$B$151/12+Assumptions!$B$153/12+Assumptions!$B$155/12+Assumptions!$B$157/12+Assumptions!$B$159/12+Assumptions!$B$161/12),0) | I23: =IF(COLUMN()-2>=Assumptions!$B$121,IF(COLUMN()-2-Assumptions!$B$121<12,Assumptions!$B$124/12+Assumptions!$B$126/12+Assumptions!$B$128/12+Assumptions!$B$130/12+Assumptions!$B$132/12+Assumptions!$B$134/12+Assumptions!$B$136/12+Assumptions!$B$138/12+Assumptions!$B$140/12+Assumptions!$B$142/12+Assumptions!$B$144/12+Assumptions!$B$146/12+Assumptions!$B$148/12+Assumptions!$B$150/12+Assumptions!$B$152/12+Assumptions!$B$154/12+Assumptions!$B$156/12+Assumptions!$B$158/12+Assumptions!$B$160/12,Assumptions!$B$125/12+Assumptions!$B$127/12+Assumptions!$B$129/12+Assumptions!$B$131/12+Assumptions!$B$133/12+Assumptions!$B$135/12+Assumptions!$B$137/12+Assumptions!$B$139/12+Assumptions!$B$141/12+Assumptions!$B$143/12+Assumptions!$B$145/12+Assumptions!$B$147/12+Assumptions!$B$149/12+Assumptions!$B$151/12+Assumptions!$B$153/12+Assumptions!$B$155/12+Assumptions!$B$157/12+Assumptions!$B$159/12+Assumptions!$B$161/12),0) | ... Y23: =IF(COLUMN()-2>=Assumptions!$B$121,IF(COLUMN()-2-Assumptions!$B$121<12,Assumptions!$B$124/12+Assumptions!$B$126/12+Assumptions!$B$128/12+Assumptions!$B$130/12+Assumptions!$B$132/12+Assumptions!$B$134/12+Assumptions!$B$136/12+Assumptions!$B$138/12+Assumptions!$B$140/12+Assumptions!$B$142/12+Assumptions!$B$144/12+Assumptions!$B$146/12+Assumptions!$B$148/12+Assumptions!$B$150/12+Assumptions!$B$152/12+Assumptions!$B$154/12+Assumptions!$B$156/12+Assumptions!$B$158/12+Assumptions!$B$160/12,Assumptions!$B$125/12+Assumptions!$B$127/12+Assumptions!$B$129/12+Assumptions!$B$131/12+Assumptions!$B$133/12+Assumptions!$B$135/12+Assumptions!$B$137/12+Assumptions!$B$139/12+Assumptions!$B$141/12+Assumptions!$B$143/12+Assumptions!$B$145/12+Assumptions!$B$147/12+Assumptions!$B$149/12+Assumptions!$B$151/12+Assumptions!$B$153/12+Assumptions!$B$155/12+Assumptions!$B$157/12+Assumptions!$B$159/12+Assumptions!$B$161/12),0)
A24: US DFS Compliance Overhead | B24: =IF(COLUMN()-2>=Assumptions!$B$121,Assumptions!$B$164/12+Assumptions!$B$165/12+Assumptions!$B$166/12+Assumptions!$B$167/12+Assumptions!$B$168/12+Assumptions!$B$169/12+Revenue!B20*Assumptions!$B$171*Assumptions!$B$170,0) | C24: =IF(COLUMN()-2>=Assumptions!$B$121,Assumptions!$B$164/12+Assumptions!$B$165/12+Assumptions!$B$166/12+Assumptions!$B$167/12+Assumptions!$B$168/12+Assumptions!$B$169/12+Revenue!C20*Assumptions!$B$171*Assumptions!$B$170,0) | D24: =IF(COLUMN()-2>=Assumptions!$B$121,Assumptions!$B$164/12+Assumptions!$B$165/12+Assumptions!$B$166/12+Assumptions!$B$167/12+Assumptions!$B$168/12+Assumptions!$B$169/12+Revenue!D20*Assumptions!$B$171*Assumptions!$B$170,0) | E24: =IF(COLUMN()-2>=Assumptions!$B$121,Assumptions!$B$164/12+Assumptions!$B$165/12+Assumptions!$B$166/12+Assumptions!$B$167/12+Assumptions!$B$168/12+Assumptions!$B$169/12+Revenue!E20*Assumptions!$B$171*Assumptions!$B$170,0) | F24: =IF(COLUMN()-2>=Assumptions!$B$121,Assumptions!$B$164/12+Assumptions!$B$165/12+Assumptions!$B$166/12+Assumptions!$B$167/12+Assumptions!$B$168/12+Assumptions!$B$169/12+Revenue!F20*Assumptions!$B$171*Assumptions!$B$170,0) | G24: =IF(COLUMN()-2>=Assumptions!$B$121,Assumptions!$B$164/12+Assumptions!$B$165/12+Assumptions!$B$166/12+Assumptions!$B$167/12+Assumptions!$B$168/12+Assumptions!$B$169/12+Revenue!G20*Assumptions!$B$171*Assumptions!$B$170,0) | H24: =IF(COLUMN()-2>=Assumptions!$B$121,Assumptions!$B$164/12+Assumptions!$B$165/12+Assumptions!$B$166/12+Assumptions!$B$167/12+Assumptions!$B$168/12+Assumptions!$B$169/12+Revenue!H20*Assumptions!$B$171*Assumptions!$B$170,0) | I24: =IF(COLUMN()-2>=Assumptions!$B$121,Assumptions!$B$164/12+Assumptions!$B$165/12+Assumptions!$B$166/12+Assumptions!$B$167/12+Assumptions!$B$168/12+Assumptions!$B$169/12+Revenue!I20*Assumptions!$B$171*Assumptions!$B$170,0) | ... Y24: =IF(COLUMN()-2>=Assumptions!$B$121,Assumptions!$B$164/12+Assumptions!$B$165/12+Assumptions!$B$166/12+Assumptions!$B$167/12+Assumptions!$B$168/12+Assumptions!$B$169/12+Revenue!Y20*Assumptions!$B$171*Assumptions!$B$170,0)
A25: Total US DFS Expansion | B25: =B23+B24 | C25: =C23+C24 | D25: =D23+D24 | E25: =E23+E24 | F25: =F23+F24 | G25: =G23+G24 | H25: =H23+H24 | I25: =I23+I24 | ... Y25: =Y23+Y24
A26: Apple Developer Program | B26: =Assumptions!$B$70/12 | C26: =Assumptions!$B$70/12 | D26: =Assumptions!$B$70/12 | E26: =Assumptions!$B$70/12 | F26: =Assumptions!$B$70/12 | G26: =Assumptions!$B$70/12 | H26: =Assumptions!$B$70/12 | I26: =Assumptions!$B$70/12 | ... Y26: =Assumptions!$B$70/12
A27: Google Play Registration | B27: =IF(COLUMN()=2,Assumptions!$B$71,0) | C27: =IF(COLUMN()=2,Assumptions!$B$71,0) | D27: =IF(COLUMN()=2,Assumptions!$B$71,0) | E27: =IF(COLUMN()=2,Assumptions!$B$71,0) | F27: =IF(COLUMN()=2,Assumptions!$B$71,0) | G27: =IF(COLUMN()=2,Assumptions!$B$71,0) | H27: =IF(COLUMN()=2,Assumptions!$B$71,0) | I27: =IF(COLUMN()=2,Assumptions!$B$71,0) | ... Y27: =IF(COLUMN()=2,Assumptions!$B$71,0)
A28: Total G&A | B28: =B20+B21+B22+B25+B26+B27 | C28: =C20+C21+C22+C25+C26+C27 | D28: =D20+D21+D22+D25+D26+D27 | E28: =E20+E21+E22+E25+E26+E27 | F28: =F20+F21+F22+F25+F26+F27 | G28: =G20+G21+G22+G25+G26+G27 | H28: =H20+H21+H22+H25+H26+H27 | I28: =I20+I21+I22+I25+I26+I27 | ... Y28: =Y20+Y21+Y22+Y25+Y26+Y27
A30: CONFERENCE & TRAVEL
A31: Conference Costs | B31: 750 | C31: 0 | D31: 0 | E31: 4500 | F31: 0 | G31: 3500 | H31: 0 | I31: 5000 | J31: 0 | K31: 0 | L31: 4000 | M31: 5000 | N31: 500 | O31: 0 | P31: 6000 | Q31: 6000 | R31: 0 | S31: 5000 | T31: 0 | U31: 8000 | V31: 0 | W31: 0 | X31: 5000 | Y31: 6000
A32: Total Conference & Travel | B32: =B31 | C32: =C31 | D32: =D31 | E32: =E31 | F32: =F31 | G32: =G31 | H32: =H31 | I32: =I31 | ... Y32: =Y31
A34: TOTAL OPEX | B34: =B17+B28+B32 | C34: =C17+C28+C32 | D34: =D17+D28+D32 | E34: =E17+E28+E32 | F34: =F17+F28+F32 | G34: =G17+G28+G32 | H34: =H17+H28+H32 | I34: =I17+I28+I32 | ... Y34: =Y17+Y28+Y32
A36: EBITDA | B36: =B10-B34 | C36: =C10-C34 | D36: =D10-D34 | E36: =E10-E34 | F36: =F10-F34 | G36: =G10-G34 | H36: =H10-H34 | I36: =I10-I34 | ... Y36: =Y10-Y34
A37: EBITDA MARGIN % | B37: =IF(Revenue!B35<>0,B36/Revenue!B35,0) | C37: =IF(Revenue!C35<>0,C36/Revenue!C35,0) | D37: =IF(Revenue!D35<>0,D36/Revenue!D35,0) | E37: =IF(Revenue!E35<>0,E36/Revenue!E35,0) | F37: =IF(Revenue!F35<>0,F36/Revenue!F35,0) | G37: =IF(Revenue!G35<>0,G36/Revenue!G35,0) | H37: =IF(Revenue!H35<>0,H36/Revenue!H35,0) | I37: =IF(Revenue!I35<>0,I36/Revenue!I35,0) | ... Y37: =IF(Revenue!Y35<>0,Y36/Revenue!Y35,0)
A39: NET INCOME | B39: =B36 | C39: =C36 | D39: =D36 | E39: =E36 | F39: =F36 | G39: =G36 | H39: =H36 | I39: =I36 | ... Y39: =Y36

Sheet Unit Economics
A1: Metric | B1: Apr-26 | C1: May-26 | D1: Jun-26 | E1: Jul-26 | F1: Aug-26 | G1: Sep-26 | H1: Oct-26 | I1: Nov-26 | J1: Dec-26 | K1: Jan-27 | L1: Feb-27 | M1: Mar-27 | N1: Apr-27 | O1: May-27 | P1: Jun-27 | Q1: Jul-27 | R1: Aug-27 | S1: Sep-27 | T1: Oct-27 | U1: Nov-27 | V1: Dec-27 | W1: Jan-28 | X1: Feb-28 | Y1: Mar-28
A2: ARPU (Total) — Net Rev / Users | B2: =IF('User Growth'!B20>0,Revenue!B35/'User Growth'!B20,0) | C2: =IF('User Growth'!C20>0,Revenue!C35/'User Growth'!C20,0) | D2: =IF('User Growth'!D20>0,Revenue!D35/'User Growth'!D20,0) | E2: =IF('User Growth'!E20>0,Revenue!E35/'User Growth'!E20,0) | F2: =IF('User Growth'!F20>0,Revenue!F35/'User Growth'!F20,0) | G2: =IF('User Growth'!G20>0,Revenue!G35/'User Growth'!G20,0) | H2: =IF('User Growth'!H20>0,Revenue!H35/'User Growth'!H20,0) | I2: =IF('User Growth'!I20>0,Revenue!I35/'User Growth'!I20,0) | ... Y2: =IF('User Growth'!Y20>0,Revenue!Y35/'User Growth'!Y20,0)
A3: ARPU (Paid) — Sub Rev / Paid | B3: =IF(B4>0,Revenue!B9/B4,0) | C3: =IF(C4>0,Revenue!C9/C4,0) | D3: =IF(D4>0,Revenue!D9/D4,0) | E3: =IF(E4>0,Revenue!E9/E4,0) | F3: =IF(F4>0,Revenue!F9/F4,0) | G3: =IF(G4>0,Revenue!G9/G4,0) | H3: =IF(H4>0,Revenue!H9/H4,0) | I3: =IF(I4>0,Revenue!I9/I4,0) | ... Y3: =IF(Y4>0,Revenue!Y9/Y4,0)
A4: Paid Subscribers | B4: ='User Growth'!B18+'User Growth'!B19 | C4: ='User Growth'!C18+'User Growth'!C19 | D4: ='User Growth'!D18+'User Growth'!D19 | E4: ='User Growth'!E18+'User Growth'!E19 | F4: ='User Growth'!F18+'User Growth'!F19 | G4: ='User Growth'!G18+'User Growth'!G19 | H4: ='User Growth'!H18+'User Growth'!H19 | I4: ='User Growth'!I18+'User Growth'!I19 | ... Y4: ='User Growth'!Y18+'User Growth'!Y19
A5: Blended Monthly Churn (Paid) | B5: =IF(B4+'User Growth'!B12+'User Growth'!B13>0,('User Growth'!B12+'User Growth'!B13)/(B4+'User Growth'!B12+'User Growth'!B13),0) | C5: =IF(C4+'User Growth'!C12+'User Growth'!C13>0,('User Growth'!C12+'User Growth'!C13)/(C4+'User Growth'!C12+'User Growth'!C13),0) | D5: =IF(D4+'User Growth'!D12+'User Growth'!D13>0,('User Growth'!D12+'User Growth'!D13)/(D4+'User Growth'!D12+'User Growth'!D13),0) | E5: =IF(E4+'User Growth'!E12+'User Growth'!E13>0,('User Growth'!E12+'User Growth'!E13)/(E4+'User Growth'!E12+'User Growth'!E13),0) | F5: =IF(F4+'User Growth'!F12+'User Growth'!F13>0,('User Growth'!F12+'User Growth'!F13)/(F4+'User Growth'!F12+'User Growth'!F13),0) | G5: =IF(G4+'User Growth'!G12+'User Growth'!G13>0,('User Growth'!G12+'User Growth'!G13)/(G4+'User Growth'!G12+'User Growth'!G13),0) | H5: =IF(H4+'User Growth'!H12+'User Growth'!H13>0,('User Growth'!H12+'User Growth'!H13)/(H4+'User Growth'!H12+'User Growth'!H13),0) | I5: =IF(I4+'User Growth'!I12+'User Growth'!I13>0,('User Growth'!I12+'User Growth'!I13)/(I4+'User Growth'!I12+'User Growth'!I13),0) | ... Y5: =IF(Y4+'User Growth'!Y12+'User Growth'!Y13>0,('User Growth'!Y12+'User Growth'!Y13)/(Y4+'User Growth'!Y12+'User Growth'!Y13),0)
A6: Implied LTV (ARPU / Churn) | B6: =IF(B5>0,B3/B5,0) | C6: =IF(C5>0,C3/C5,0) | D6: =IF(D5>0,D3/D5,0) | E6: =IF(E5>0,E3/E5,0) | F6: =IF(F5>0,F3/F5,0) | G6: =IF(G5>0,G3/G5,0) | H6: =IF(H5>0,H3/H5,0) | I6: =IF(I5>0,I3/I5,0) | ... Y6: =IF(Y5>0,Y3/Y5,0)
A7: CAC (S&M / New Users) | B7: =IF('User Growth'!B3>0,'COGS & Operating Expenses'!B17/'User Growth'!B3,0) | C7: =IF('User Growth'!C3>0,'COGS & Operating Expenses'!C17/'User Growth'!C3,0) | D7: =IF('User Growth'!D3>0,'COGS & Operating Expenses'!D17/'User Growth'!D3,0) | E7: =IF('User Growth'!E3>0,'COGS & Operating Expenses'!E17/'User Growth'!E3,0) | F7: =IF('User Growth'!F3>0,'COGS & Operating Expenses'!F17/'User Growth'!F3,0) | G7: =IF('User Growth'!G3>0,'COGS & Operating Expenses'!G17/'User Growth'!G3,0) | H7: =IF('User Growth'!H3>0,'COGS & Operating Expenses'!H17/'User Growth'!H3,0) | I7: =IF('User Growth'!I3>0,'COGS & Operating Expenses'!I17/'User Growth'!I3,0) | ... Y7: =IF('User Growth'!Y3>0,'COGS & Operating Expenses'!Y17/'User Growth'!Y3,0)
A8: LTV:CAC Ratio | B8: =IF(B7>0,B6/B7,0) | C8: =IF(C7>0,C6/C7,0) | D8: =IF(D7>0,D6/D7,0) | E8: =IF(E7>0,E6/E7,0) | F8: =IF(F7>0,F6/F7,0) | G8: =IF(G7>0,G6/G7,0) | H8: =IF(H7>0,H6/H7,0) | I8: =IF(I7>0,I6/I7,0) | ... Y8: =IF(Y7>0,Y6/Y7,0)
A9: Payback Period (months) | B9: =IF(B3>0,B7/B3,0) | C9: =IF(C3>0,C7/C3,0) | D9: =IF(D3>0,D7/D3,0) | E9: =IF(E3>0,E7/E3,0) | F9: =IF(F3>0,F7/F3,0) | G9: =IF(G3>0,G7/G3,0) | H9: =IF(H3>0,H7/H3,0) | I9: =IF(I3>0,I7/I3,0) | ... Y9: =IF(Y3>0,Y7/Y3,0)
A10: Team Size (approx) | B10: =IF(COLUMN()-2<6,0,IF(COLUMN()-2<12,1,IF(COLUMN()-2<18,2,3))) | C10: =IF(COLUMN()-2<6,0,IF(COLUMN()-2<12,1,IF(COLUMN()-2<18,2,3))) | D10: =IF(COLUMN()-2<6,0,IF(COLUMN()-2<12,1,IF(COLUMN()-2<18,2,3))) | E10: =IF(COLUMN()-2<6,0,IF(COLUMN()-2<12,1,IF(COLUMN()-2<18,2,3))) | F10: =IF(COLUMN()-2<6,0,IF(COLUMN()-2<12,1,IF(COLUMN()-2<18,2,3))) | G10: =IF(COLUMN()-2<6,0,IF(COLUMN()-2<12,1,IF(COLUMN()-2<18,2,3))) | H10: =IF(COLUMN()-2<6,0,IF(COLUMN()-2<12,1,IF(COLUMN()-2<18,2,3))) | I10: =IF(COLUMN()-2<6,0,IF(COLUMN()-2<12,1,IF(COLUMN()-2<18,2,3))) | ... Y10: =IF(COLUMN()-2<6,0,IF(COLUMN()-2<12,1,IF(COLUMN()-2<18,2,3)))
A11: Revenue Per Employee | B11: =IF(B10>0,Revenue!B35/B10,0) | C11: =IF(C10>0,Revenue!C35/C10,0) | D11: =IF(D10>0,Revenue!D35/D10,0) | E11: =IF(E10>0,Revenue!E35/E10,0) | F11: =IF(F10>0,Revenue!F35/F10,0) | G11: =IF(G10>0,Revenue!G35/G10,0) | H11: =IF(H10>0,Revenue!H35/H10,0) | I11: =IF(I10>0,Revenue!I35/I10,0) | ... Y11: =IF(Y10>0,Revenue!Y35/Y10,0)

Sheet Cash Flow & Runway
A1: Cash Flow | B1: Apr-26 | C1: May-26 | D1: Jun-26 | E1: Jul-26 | F1: Aug-26 | G1: Sep-26 | H1: Oct-26 | I1: Nov-26 | J1: Dec-26 | K1: Jan-27 | L1: Feb-27 | M1: Mar-27 | N1: Apr-27 | O1: May-27 | P1: Jun-27 | Q1: Jul-27 | R1: Aug-27 | S1: Sep-27 | T1: Oct-27 | U1: Nov-27 | V1: Dec-27 | W1: Jan-28 | X1: Feb-28 | Y1: Mar-28
A2: Starting Cash | B2: =Assumptions!$B$200
A3: Monthly Net Income (EBITDA) | B3: ='COGS & Operating Expenses'!B36 | C3: ='COGS & Operating Expenses'!C36 | D3: ='COGS & Operating Expenses'!D36 | E3: ='COGS & Operating Expenses'!E36 | F3: ='COGS & Operating Expenses'!F36 | G3: ='COGS & Operating Expenses'!G36 | H3: ='COGS & Operating Expenses'!H36 | I3: ='COGS & Operating Expenses'!I36 | ... Y3: ='COGS & Operating Expenses'!Y36
A4: Cumulative Cash Position | B4: =Assumptions!$B$200+B3 | C4: =B4+C3 | D4: =C4+D3 | E4: =D4+E3 | F4: =E4+F3 | G4: =F4+G3 | H4: =G4+H3 | I4: =H4+I3 | J4: =I4+J3 | ... Y4: =X4+Y3
A5: Monthly Burn Rate | B5: =IF(B3<0,-B3,0) | C5: =IF(C3<0,-C3,0) | D5: =IF(D3<0,-D3,0) | E5: =IF(E3<0,-E3,0) | F5: =IF(F3<0,-F3,0) | G5: =IF(G3<0,-G3,0) | H5: =IF(H3<0,-H3,0) | I5: =IF(I3<0,-I3,0) | ... Y5: =IF(Y3<0,-Y3,0)
A6: Runway (months) | B6: =IF(AND(B5>0,B4>0),B4/B5,0) | C6: =IF(AND(C5>0,C4>0),C4/C5,0) | D6: =IF(AND(D5>0,D4>0),D4/D5,0) | E6: =IF(AND(E5>0,E4>0),E4/E5,0) | F6: =IF(AND(F5>0,F4>0),F4/F5,0) | G6: =IF(AND(G5>0,G4>0),G4/G5,0) | H6: =IF(AND(H5>0,H4>0),H4/H5,0) | I6: =IF(AND(I5>0,I4>0),I4/I5,0) | ... Y6: =IF(AND(Y5>0,Y4>0),Y4/Y5,0)
A8: Cash Flow Positive Month: | B8: =IFERROR(INDEX(B1:Y1,MATCH(TRUE,B3:Y3>0,0)),"Not within 24 months")

Sheet Annual Summary
A1: Metric | B1: Year 1 (Apr 26-Mar 27) | C1: Year 2 (Apr 27-Mar 28) | D1: YoY Growth %
A2: KEY METRICS
A3: End-of-Year Total Users | B3: ='User Growth'!M20 | C3: ='User Growth'!Y20 | D3: =IF(ABS(B3)>0,(C3-B3)/ABS(B3),0)
A4: End-of-Year Pro Users | B4: ='User Growth'!M18 | C4: ='User Growth'!Y18 | D4: =IF(ABS(B4)>0,(C4-B4)/ABS(B4),0)
A5: End-of-Year Commissioner Users | B5: ='User Growth'!M19 | C5: ='User Growth'!Y19 | D5: =IF(ABS(B5)>0,(C5-B5)/ABS(B5),0)
A7: REVENUE
A8: Net Subscription Revenue | B8: =SUM(Revenue!B9:Revenue!M9) | C8: =SUM(Revenue!N9:Revenue!Y9) | D8: =IF(ABS(B8)>0,(C8-B8)/ABS(B8),0)
A9: Pay-Per-Use Revenue | B9: =SUM(Revenue!B15:Revenue!M15) | C9: =SUM(Revenue!N15:Revenue!Y15) | D9: =IF(ABS(B9)>0,(C9-B9)/ABS(B9),0)
A10: DFS Rake Revenue | B10: =SUM(Revenue!B20:Revenue!M20) | C10: =SUM(Revenue!N20:Revenue!Y20) | D10: =IF(ABS(B10)>0,(C10-B10)/ABS(B10),0)
A11: Advertising Revenue | B11: =SUM(Revenue!B25:Revenue!M25) | C11: =SUM(Revenue!N25:Revenue!Y25) | D11: =IF(ABS(B11)>0,(C11-B11)/ABS(B11),0)
A12: Gross Revenue | B12: =SUM(Revenue!B27:Revenue!M27) | C12: =SUM(Revenue!N27:Revenue!Y27) | D12: =IF(ABS(B12)>0,(C12-B12)/ABS(B12),0)
A13: Platform Fees | B13: =SUM(Revenue!B33:Revenue!M33) | C13: =SUM(Revenue!N33:Revenue!Y33) | D13: =IF(ABS(B13)>0,(C13-B13)/ABS(B13),0)
A14: Net Revenue | B14: =SUM(Revenue!B35:Revenue!M35) | C14: =SUM(Revenue!N35:Revenue!Y35) | D14: =IF(ABS(B14)>0,(C14-B14)/ABS(B14),0)
A16: COSTS
A17: Total COGS | B17: =SUM('COGS & Operating Expenses'!B8:'COGS & Operating Expenses'!M8) | C17: =SUM('COGS & Operating Expenses'!N8:'COGS & Operating Expenses'!Y8) | D17: =IF(ABS(B17)>0,(C17-B17)/ABS(B17),0)
A18: Gross Profit | B18: =SUM('COGS & Operating Expenses'!B10:'COGS & Operating Expenses'!M10) | C18: =SUM('COGS & Operating Expenses'!N10:'COGS & Operating Expenses'!Y10) | D18: =IF(ABS(B18)>0,(C18-B18)/ABS(B18),0)
A19: Sales & Marketing | B19: =SUM('COGS & Operating Expenses'!B17:'COGS & Operating Expenses'!M17) | C19: =SUM('COGS & Operating Expenses'!N17:'COGS & Operating Expenses'!Y17) | D19: =IF(ABS(B19)>0,(C19-B19)/ABS(B19),0)
A20: DFS Regulatory — Canada | B20: =SUM('COGS & Operating Expenses'!B22:'COGS & Operating Expenses'!M22) | C20: =SUM('COGS & Operating Expenses'!N22:'COGS & Operating Expenses'!Y22) | D20: =IF(ABS(B20)>0,(C20-B20)/ABS(B20),0)
A21: US DFS Expansion (Total) | B21: =SUM('COGS & Operating Expenses'!B25:'COGS & Operating Expenses'!M25) | C21: =SUM('COGS & Operating Expenses'!N25:'COGS & Operating Expenses'!Y25) | D21: =IF(ABS(B21)>0,(C21-B21)/ABS(B21),0)
A22: Total OPEX | B22: =SUM('COGS & Operating Expenses'!B34:'COGS & Operating Expenses'!M34) | C22: =SUM('COGS & Operating Expenses'!N34:'COGS & Operating Expenses'!Y34) | D22: =IF(ABS(B22)>0,(C22-B22)/ABS(B22),0)
